<?xml version="1.0" encoding="utf-8"?>
<robot name="pro" xmlns:xacro="http://ros.org/wiki/xacro">

<!-- color -->
  <material name="black">
    <color rgba="0.2 0.2 0.2 1" />
  </material>
  <material name="grey">
    <color rgba="0.5 0.5 0.5 1.0" />
  </material>
  <material name="blue">
    <color rgba="0.0 0.0 0.8 1.0" />
  </material>
  <material name="white">
    <color rgba="0.792156862745098 0.819607843137255 0.933333333333333 1" />
  </material>
  <material name="red">
    <color rgba="1 0 0 1" />
  </material>

<!-- base link -->
  <link name="base_link">
    <inertial>
      <origin xyz="0.00110722546972766 -0.000881363789764601 0.000896456868487516" rpy="0 0 0" />
      <mass value="0.55074908504643" />
      <inertia
        ixx="0.000515892591088768"
        ixy="3.51265993938339E-06"
        ixz="-1.07236227973216E-07"
        iyy="0.000989448211818998"
        iyz="-1.2825575037116E-07"
        izz="0.00142165209596468" />
    </inertial>
    <visual>
      <origin xyz="0 0 0" rpy="0 0 0" />
      <geometry>
        <mesh filename="package://iron_x/meshes/base_link.STL" />
      </geometry>
      <material name="white" />
    </visual>
    <collision>
      <origin xyz="0 0 0" rpy="0 0 0" />
      <geometry>
        <mesh filename="package://iron_x/meshes/base_link.STL" />
      </geometry>
    </collision>
  </link>

  <gazebo reference="base_link">
    <material>Gazebo/White</material>
  </gazebo>

<!-- base_footprint -->
  <link name="base_footprint"/>

  <joint name="base_joint" type="fixed">
    <parent link="base_footprint"/>
    <child link="base_link"/>
    <origin xyz="0.0 0.0 0.06" rpy="0 0 0"/>
  </joint>

<!-- lf -->
  <link name="left_front_link">
    <inertial>
      <origin xyz="0.000194225316144145 -0.000828209013987113 0.000986492502320621" rpy="0 0 0" />
      <mass value="0.232754018244587" />
      <inertia
        ixx="6.60491736740839E-05"
        ixy="5.65423279156466E-08"
        ixz="-2.15031963946931E-07"
        iyy="6.58573686281087E-05"
        iyz="-5.88454152671157E-08"
        izz="9.9502807224037E-05" />
    </inertial>
    <visual>
      <origin xyz="0 0 0" rpy="0 0 0" />
      <geometry>
        <mesh filename="package://iron_x/meshes/left_front_link.STL" />
      </geometry>
      <material name="black"/>
    </visual>
    <collision>
      <origin xyz="0 0 0" rpy="0 0 0" />
      <geometry>
        <mesh filename="package://iron_x/meshes/left_front_link.STL" />
      </geometry>
    </collision>
  </link>

  <joint name="left_front_joint" type="continuous">
    <origin xyz="0.074805 0.095021 -0.016504" rpy="1.5708 0 0" />
    <parent link="base_link" />
    <child link="left_front_link" />
    <axis xyz="0 0 -1" />
  </joint>

  <gazebo reference="left_front_link">
    <material>Gazebo/Black</material>
  </gazebo>

<!-- rf -->
  <link name="right_front_link">
    <inertial>
      <origin xyz="0.000792045383486775 -0.000327398755852741 -0.00097139380563907" rpy="0 0 0" />
      <mass value="0.23298424820783" />
      <inertia
        ixx="6.58754749146013E-05"
        ixy="7.86279996081456E-08"
        ixz="8.49550351004516E-08"
        iyy="6.60326041337809E-05"
        iyz="2.06255946908732E-07"
        izz="9.95032142784321E-05" />
    </inertial>
    <visual>
      <origin xyz="0 0 0" rpy="0 0 0" />
      <geometry>
        <mesh filename="package://iron_x/meshes/right_front_link.STL" />
      </geometry>
      <material name="black"/>
    </visual>
    <collision>
      <origin xyz="0 0 0" rpy="0 0 0" />
      <geometry>
        <mesh filename="package://iron_x/meshes/right_front_link.STL" />
      </geometry>
    </collision>
  </link>

  <joint name="right_front_joint" type="continuous">
    <origin xyz="0.074805 -0.094979 -0.016504" rpy="1.5708 0 0" />
    <parent link="base_link" />
    <child link="right_front_link" />
    <axis xyz="0 0 1" />
  </joint>

  <gazebo reference="right_front_link">
    <material>Gazebo/Black</material>
  </gazebo>

<!-- rb -->
  <link name="right_back_link">
    <inertial>
      <origin xyz="-0.000773470199692303 -0.000353801232542403 -0.000986487989111592" rpy="0 0 0" />
      <mass value="0.232753618913786" />
      <inertia
        ixx="6.5874517458556E-05"
        ixy="-7.88341300118085E-08"
        ixz="-8.51211993149177E-08"
        iyy="6.60315992760322E-05"
        iyz="2.05846020987768E-07"
        izz="9.95023481099526E-05" />
    </inertial>
    <visual>
      <origin xyz="0 0 0" rpy="0 0 0" />
      <geometry>
        <mesh filename="package://iron_x/meshes/right_back_link.STL" />
      </geometry>
      <material name="black"/>
    </visual>
    <collision>
      <origin xyz="0 0 0" rpy="0 0 0" />
      <geometry>
        <mesh filename="package://iron_x/meshes/right_back_link.STL" />
      </geometry>
    </collision>
  </link>

  <joint name="right_back_joint" type="continuous">
    <origin xyz="-0.075684 -0.094979 -0.016504" rpy="-1.5708 0 0" />
    <parent link="base_link" />
    <child link="right_back_link" />
    <axis xyz="0 0 1" />
  </joint>

  <gazebo reference="right_back_link">
    <material>Gazebo/Black</material>
  </gazebo>

<!-- lb -->
  <link name="left_back_link">
    <inertial>
      <origin xyz="-0.000792048600706974 -0.000327401208942674 0.000971393876159951" rpy="0 0 0" />
      <mass value="0.232984248959823" />
      <inertia
        ixx="6.58754747457331E-05"
        ixy="-7.86281708586474E-08"
        ixz="8.49525974156277E-08"
        iyy="6.60326034401508E-05"
        iyz="-2.06258052484318E-07"
        izz="9.95032135393818E-05" />
    </inertial>
    <visual>
      <origin xyz="0 0 0" rpy="0 0 0" />
      <geometry>
        <mesh filename="package://iron_x/meshes/left_back_link.STL" />
      </geometry>
      <material name="black"/>
    </visual>
    <collision>
      <origin xyz="0 0 0" rpy="0 0 0" />
      <geometry>
        <mesh filename="package://iron_x/meshes/left_back_link.STL" />
      </geometry>
    </collision>
  </link>

  <joint name="left_back_joint" type="continuous">
    <origin xyz="-0.075684 0.095021 -0.016504" rpy="1.5708 0 0" />
    <parent link="base_link" />
    <child link="left_back_link" />
    <axis xyz="0 0 -1" />
  </joint>

  <gazebo reference="left_back_link">
    <material>Gazebo/Black</material>
  </gazebo>

<!-- cam  -->
  <link name="camera_link">
    <inertial>
      <origin xyz="-0.000367790326270767 0.00323906965269144 -5.30738632309041E-05" rpy="0 0 0" />
      <mass value="0.040528016503577" />
      <inertia
        ixx="4.05785979538911E-05"
        ixy="3.56539280580418E-07"
        ixz="4.66370532236397E-08"
        iyy="3.49041875072854E-06"
        iyz="3.88944445461142E-07"
        izz="3.74941507176843E-05" />
    </inertial>
    <visual>
      <origin xyz="0 0 0" rpy="0 0 0" />
      <geometry>
        <mesh filename="package://iron_x/meshes/camera_link.STL" />
      </geometry>
      <material name="grey"/>
    </visual>
    <collision>
      <origin xyz="0 0 0" rpy="0 0 0" />
      <geometry>
        <mesh filename="package://iron_x/meshes/camera_link.STL" />
      </geometry>
    </collision>
  </link>
  <joint name="camera_joint" type="fixed">
    <origin xyz="0.11646 1.7971E-05 0.058" rpy="0 0 0" />
    <parent link="base_link" />
    <child link="camera_link" />
    <axis xyz="0 0 0" />
  </joint>

  <link name="camera_rgb_frame"/>
  <joint name="camera_rgb_joint" type="fixed">
    <origin xyz="0 0 0" rpy="-1.57 0 -1.57"/>
    <parent link="camera_link"/>
    <child link="camera_rgb_frame"/>
  </joint>

  <gazebo reference="camera_link">
    <material>Gazebo/Grey</material>
  </gazebo>

  <gazebo reference="camera_link">
    <sensor name="camera" type="depth">
      <always_on>true</always_on>
      <visualize>true</visualize>
      <update_rate>20.0</update_rate>
      <camera name="intel_realsense">
        <horizontal_fov>0.55</horizontal_fov>
        <image>
          <width>640</width>
          <height>480</height>
          <format>R8G8B8</format>
        </image>
        <clip>
          <near>0.2</near>
          <far>20</far>
        </clip>
        <noise>
          <type>gaussian</type>
          <mean>0.0</mean>
          <stddev>0.007</stddev>
        </noise>
      </camera>
      <plugin name="depth_camera_controller" filename="libgazebo_ros_camera.so">
        <baseline>0.2</baseline>
        <alwaysOn>true</alwaysOn>
        <updateRate>20.0</updateRate>
        <frame_name>camera_rgb_frame</frame_name>
        <pointCloudCutoff>0.5</pointCloudCutoff>
        <pointCloudCutoffMax>3.0</pointCloudCutoffMax>
        <distortionK1>0</distortionK1>
        <distortionK2>0</distortionK2>
        <distortionK3>0</distortionK3>
        <distortionT1>0</distortionT1>
        <distortionT2>0</distortionT2>
        <CxPrime>0</CxPrime>
        <Cx>0</Cx>
        <Cy>0</Cy>
        <focalLength>0</focalLength>
        <hackBaseline>0</hackBaseline>
      </plugin>
    </sensor>
  </gazebo>

<!-- rp -->
  <link name="lidar_link">
    <inertial>
      <origin xyz="8.38413796889446E-05 -9.42035183245905E-05 -0.0165835731091839" rpy="0 0 0" />
      <mass value="0.032404615890783" />
      <inertia
        ixx="1.08405105236319E-05"
        ixy="-2.3933156084419E-09"
        ixz="1.61833884660667E-08"
        iyy="1.07831255822121E-05"
        iyz="-4.19844857280673E-09"
        izz="1.96305335345869E-05" />
    </inertial>
    <visual>
      <origin xyz="0 0 0" rpy="0 0 0" />
      <geometry>
        <mesh filename="package://iron_x/meshes/lidar_link.STL" />
      </geometry>
      <material name="grey"/>
    </visual>
    <collision>
      <origin xyz="0 0 0" rpy="0 0 0" />
      <geometry>
        <mesh filename="package://iron_x/meshes/lidar_link.STL" />
      </geometry>
    </collision>
  </link>

  <joint name="lidar_joint" type="fixed">
    <origin xyz="0.024561 2.068E-05 0.080078" rpy="0 0 0" />
    <parent link="base_link" />
    <child link="lidar_link" />
    <axis xyz="0 0 -1" />
  </joint>

  <gazebo reference="lidar_link">
    <material>Gazebo/Grey</material>
  </gazebo>

  <gazebo reference="lidar_link">
    <sensor name="RPlidar" type="ray">
      <always_on>true</always_on>
      <visualize>true</visualize>
      <update_rate>5</update_rate>
      <ray>
        <scan>
          <horizontal>
            <samples>360</samples>
            <resolution>1.000000</resolution>
            <min_angle>0.000000</min_angle>
            <max_angle>6.280000</max_angle>
          </horizontal>
        </scan>
        <range>
          <min>0.15</min>
          <max>12.0</max>
          <resolution>0.015000</resolution>
        </range>
        <noise>
          <type>gaussian</type>
          <mean>0.0</mean>
          <stddev>0.01</stddev>
        </noise>
      </ray>
      <plugin name="scan" filename="libgazebo_ros_ray_sensor.so">
        <ros>
          <remapping>~/out:=scan</remapping>
        </ros>
        <output_type>sensor_msgs/LaserScan</output_type>
        <frame_name>lidar_link</frame_name>
      </plugin>
    </sensor>
  </gazebo>

<!-- imu -->
  <link name="imu_link">
    <inertial>
      <origin xyz="-0.00165537333783889 0.000107786090904231 -0.000448013789479707" rpy="0 0 0" />
      <mass value="0.000529381774423456" />
      <inertia
        ixx="1.33292005146446E-08"
        ixy="5.60536119209215E-12"
        ixz="-6.25784169122668E-14"
        iyy="7.56085417916531E-09"
        iyz="2.9897203630263E-17"
        izz="1.99747898140485E-08" />
    </inertial>
    <visual>
      <origin xyz="0 0 0" rpy="0 0 0" />
      <geometry>
        <mesh filename="package://iron_x/meshes/imu_link.STL" />
      </geometry>
      <material name="red"/>
    </visual>
    <collision>
      <origin xyz="0 0 0" rpy="0 0 0" />
      <geometry>
        <mesh filename="package://iron_x/meshes/imu_link.STL" />
      </geometry>
    </collision>
  </link>

  <joint name="imu_joint" type="fixed">
    <origin xyz="-0.00043943 2.068E-05 0.0020715" rpy="0 0 0" />
    <parent link="base_link" />
    <child link="imu_link" />
    <axis xyz="0 0 0" />
  </joint>

  <gazebo reference="imu_link">
    <material>Gazebo/Red</material>
  </gazebo>

  <gazebo reference="imu_link">
    <gravity>true</gravity>
    <sensor name="twr_imu" type="imu">
      <always_on>true</always_on>
      <update_rate>20</update_rate>
      <visualize>true</visualize>
      <imu>
        <orientation>
          <x>
            <noise type="gaussian">
              <mean>0.0</mean>
              <stddev>2e-3</stddev>
            </noise>
          </x>
          <y>
            <noise type="gaussian">
              <mean>0.0</mean>
              <stddev>2e-3</stddev>
            </noise>
          </y>
          <z>
            <noise type="gaussian">
              <mean>0.0</mean>
              <stddev>2e-3</stddev>
            </noise>
          </z>
        </orientation>
        <angular_velocity>
          <x>
            <noise type="gaussian">
              <mean>0.0</mean>
              <stddev>2e-4</stddev>
            </noise>
          </x>
          <y>
            <noise type="gaussian">
              <mean>0.0</mean>
              <stddev>2e-4</stddev>
            </noise>
          </y>
          <z>
            <noise type="gaussian">
              <mean>0.0</mean>
              <stddev>2e-4</stddev>
            </noise>
          </z>
        </angular_velocity>
        <linear_acceleration>
          <x>
            <noise type="gaussian">
              <mean>0.0</mean>
              <stddev>1.7e-2</stddev>
            </noise>
          </x>
          <y>
            <noise type="gaussian">
              <mean>0.0</mean>
              <stddev>1.7e-2</stddev>
            </noise>
          </y>
          <z>
            <noise type="gaussian">
              <mean>0.0</mean>
              <stddev>1.7e-2</stddev>
            </noise>
          </z>
        </linear_acceleration>
      </imu>
      <plugin name="robot_imu" filename="libgazebo_ros_imu_sensor.so">
        <initial_orientation_as_reference>false</initial_orientation_as_reference>
        <frame_name>imu_link</frame_name>
        <ros>
          <namespace>/imu</namespace>
        </ros>
      </plugin>
    </sensor>
  </gazebo>

<!-- joint_state -->
  <gazebo>
    <plugin name="gazebo_joint_state" filename="libgazebo_ros_joint_state_publisher.so">
      <update_rate>20</update_rate>
      <joint_name>left_front_joint</joint_name>
      <joint_name>right_front_joint</joint_name>
      <joint_name>left_back_joint</joint_name>
      <joint_name>right_back_joint</joint_name>
    </plugin>
  </gazebo>

<!-- wheel -->
  <gazebo>
    <plugin name="mecanum_control" filename="libgazebo_ros_planar_move.so">
      <command_topic>cmd_vel</command_topic>
      <odometry_topic>odom</odometry_topic>
      <odometry_frame>odom</odometry_frame>
      <odometry_rate>20.0</odometry_rate>
      <robot_base_frame>base_footprint</robot_base_frame>
      <publish_odom>true</publish_odom>
      <publish_odom_tf>true</publish_odom_tf>
    </plugin>
  </gazebo>
</robot>