<?xml version="1.0" encoding="utf-8"?>
<!-- This URDF was automatically created by SolidWorks to URDF Exporter! Originally created by Stephen Brawner (brawner@gmail.com) 
     Commit Version: 1.6.0-4-g7f85cfe  Build Version: 1.6.7995.38578
     For more information, please see http://wiki.ros.org/sw_urdf_exporter -->
<robot
  name="IRON-X PRO TESR THESIS v.1">
  <link
    name="base_link">
    <inertial>
      <origin
        xyz="0.00110722546972766 -0.000881363789764601 0.000896456868487516"
        rpy="0 0 0" />
      <mass
        value="0.55074908504643" />
      <inertia
        ixx="0.000515892591088768"
        ixy="3.51265993938339E-06"
        ixz="-1.07236227973216E-07"
        iyy="0.000989448211818998"
        iyz="-1.2825575037116E-07"
        izz="0.00142165209596468" />
    </inertial>
    <visual>
      <origin
        xyz="0 0 0"
        rpy="0 0 0" />
      <geometry>
        <mesh
          filename="package://IRON-X PRO TESR THESIS v.1/meshes/base_link.STL" />
      </geometry>
      <material
        name="">
        <color
          rgba="0.792156862745098 0.819607843137255 0.933333333333333 1" />
      </material>
    </visual>
    <collision>
      <origin
        xyz="0 0 0"
        rpy="0 0 0" />
      <geometry>
        <mesh
          filename="package://IRON-X PRO TESR THESIS v.1/meshes/base_link.STL" />
      </geometry>
    </collision>
  </link>
  <link
    name="left_front_link">
    <inertial>
      <origin
        xyz="0.000194225316144145 -0.000828209013987113 0.000986492502320621"
        rpy="0 0 0" />
      <mass
        value="0.232754018244587" />
      <inertia
        ixx="6.60491736740839E-05"
        ixy="5.65423279156466E-08"
        ixz="-2.15031963946931E-07"
        iyy="6.58573686281087E-05"
        iyz="-5.88454152671157E-08"
        izz="9.9502807224037E-05" />
    </inertial>
    <visual>
      <origin
        xyz="0 0 0"
        rpy="0 0 0" />
      <geometry>
        <mesh
          filename="package://IRON-X PRO TESR THESIS v.1/meshes/left_front_link.STL" />
      </geometry>
      <material
        name="">
        <color
          rgba="0.2 0.2 0.2 1" />
      </material>
    </visual>
    <collision>
      <origin
        xyz="0 0 0"
        rpy="0 0 0" />
      <geometry>
        <mesh
          filename="package://IRON-X PRO TESR THESIS v.1/meshes/left_front_link.STL" />
      </geometry>
    </collision>
  </link>
  <joint
    name="left_front_joint"
    type="continuous">
    <origin
      xyz="0.074805 0.095021 -0.016504"
      rpy="1.5708 0 0" />
    <parent
      link="base_link" />
    <child
      link="left_front_link" />
    <axis
      xyz="0 0 -1" />
  </joint>
  <link
    name="right_front_link">
    <inertial>
      <origin
        xyz="0.000792045383486775 -0.000327398755852741 -0.00097139380563907"
        rpy="0 0 0" />
      <mass
        value="0.23298424820783" />
      <inertia
        ixx="6.58754749146013E-05"
        ixy="7.86279996081456E-08"
        ixz="8.49550351004516E-08"
        iyy="6.60326041337809E-05"
        iyz="2.06255946908732E-07"
        izz="9.95032142784321E-05" />
    </inertial>
    <visual>
      <origin
        xyz="0 0 0"
        rpy="0 0 0" />
      <geometry>
        <mesh
          filename="package://IRON-X PRO TESR THESIS v.1/meshes/right_front_link.STL" />
      </geometry>
      <material
        name="">
        <color
          rgba="0.792156862745098 0.819607843137255 0.933333333333333 1" />
      </material>
    </visual>
    <collision>
      <origin
        xyz="0 0 0"
        rpy="0 0 0" />
      <geometry>
        <mesh
          filename="package://IRON-X PRO TESR THESIS v.1/meshes/right_front_link.STL" />
      </geometry>
    </collision>
  </link>
  <joint
    name="right_front_joint"
    type="continuous">
    <origin
      xyz="0.074805 -0.094979 -0.016504"
      rpy="1.5708 0 0" />
    <parent
      link="base_link" />
    <child
      link="right_front_link" />
    <axis
      xyz="0 0 1" />
  </joint>
  <link
    name="right_back_link">
    <inertial>
      <origin
        xyz="-0.000773470199692303 -0.000353801232542403 -0.000986487989111592"
        rpy="0 0 0" />
      <mass
        value="0.232753618913786" />
      <inertia
        ixx="6.5874517458556E-05"
        ixy="-7.88341300118085E-08"
        ixz="-8.51211993149177E-08"
        iyy="6.60315992760322E-05"
        iyz="2.05846020987768E-07"
        izz="9.95023481099526E-05" />
    </inertial>
    <visual>
      <origin
        xyz="0 0 0"
        rpy="0 0 0" />
      <geometry>
        <mesh
          filename="package://IRON-X PRO TESR THESIS v.1/meshes/right_back_link.STL" />
      </geometry>
      <material
        name="">
        <color
          rgba="0.2 0.2 0.2 1" />
      </material>
    </visual>
    <collision>
      <origin
        xyz="0 0 0"
        rpy="0 0 0" />
      <geometry>
        <mesh
          filename="package://IRON-X PRO TESR THESIS v.1/meshes/right_back_link.STL" />
      </geometry>
    </collision>
  </link>
  <joint
    name="right_back_joint"
    type="continuous">
    <origin
      xyz="-0.075684 -0.094979 -0.016504"
      rpy="1.5708 0 0" />
    <parent
      link="base_link" />
    <child
      link="right_back_link" />
    <axis
      xyz="0 0 1" />
  </joint>
  <link
    name="left_back_link">
    <inertial>
      <origin
        xyz="-0.000792048600706974 -0.000327401208942674 0.000971393876159951"
        rpy="0 0 0" />
      <mass
        value="0.232984248959823" />
      <inertia
        ixx="6.58754747457331E-05"
        ixy="-7.86281708586474E-08"
        ixz="8.49525974156277E-08"
        iyy="6.60326034401508E-05"
        iyz="-2.06258052484318E-07"
        izz="9.95032135393818E-05" />
    </inertial>
    <visual>
      <origin
        xyz="0 0 0"
        rpy="0 0 0" />
      <geometry>
        <mesh
          filename="package://IRON-X PRO TESR THESIS v.1/meshes/left_back_link.STL" />
      </geometry>
      <material
        name="">
        <color
          rgba="0.792156862745098 0.819607843137255 0.933333333333333 1" />
      </material>
    </visual>
    <collision>
      <origin
        xyz="0 0 0"
        rpy="0 0 0" />
      <geometry>
        <mesh
          filename="package://IRON-X PRO TESR THESIS v.1/meshes/left_back_link.STL" />
      </geometry>
    </collision>
  </link>
  <joint
    name="left_back_joint"
    type="continuous">
    <origin
      xyz="-0.075684 0.095021 -0.016504"
      rpy="1.5708 0 0" />
    <parent
      link="base_link" />
    <child
      link="left_back_link" />
    <axis
      xyz="0 0 -1" />
  </joint>
  <link
    name="camera_link">
    <inertial>
      <origin
        xyz="-0.000367790326270767 0.00323906965269144 -5.30738632309041E-05"
        rpy="0 0 0" />
      <mass
        value="0.040528016503577" />
      <inertia
        ixx="4.05785979538911E-05"
        ixy="3.56539280580418E-07"
        ixz="4.66370532236397E-08"
        iyy="3.49041875072854E-06"
        iyz="3.88944445461142E-07"
        izz="3.74941507176843E-05" />
    </inertial>
    <visual>
      <origin
        xyz="0 0 0"
        rpy="0 0 0" />
      <geometry>
        <mesh
          filename="package://IRON-X PRO TESR THESIS v.1/meshes/camera_link.STL" />
      </geometry>
      <material
        name="">
        <color
          rgba="0.752941176470588 0.752941176470588 0.752941176470588 1" />
      </material>
    </visual>
    <collision>
      <origin
        xyz="0 0 0"
        rpy="0 0 0" />
      <geometry>
        <mesh
          filename="package://IRON-X PRO TESR THESIS v.1/meshes/camera_link.STL" />
      </geometry>
    </collision>
  </link>
  <joint
    name="camera_joint"
    type="fixed">
    <origin
      xyz="0.11646 1.7971E-05 0.058"
      rpy="0 0 0" />
    <parent
      link="base_link" />
    <child
      link="camera_link" />
    <axis
      xyz="0 0 0" />
  </joint>
  <link
    name="lidar_link">
    <inertial>
      <origin
        xyz="8.38413796889446E-05 -9.42035183245905E-05 -0.0165835731091839"
        rpy="0 0 0" />
      <mass
        value="0.032404615890783" />
      <inertia
        ixx="1.08405105236319E-05"
        ixy="-2.3933156084419E-09"
        ixz="1.61833884660667E-08"
        iyy="1.07831255822121E-05"
        iyz="-4.19844857280673E-09"
        izz="1.96305335345869E-05" />
    </inertial>
    <visual>
      <origin
        xyz="0 0 0"
        rpy="0 0 0" />
      <geometry>
        <mesh
          filename="package://IRON-X PRO TESR THESIS v.1/meshes/lidar_link.STL" />
      </geometry>
      <material
        name="">
        <color
          rgba="0.792156862745098 0.819607843137255 0.933333333333333 1" />
      </material>
    </visual>
    <collision>
      <origin
        xyz="0 0 0"
        rpy="0 0 0" />
      <geometry>
        <mesh
          filename="package://IRON-X PRO TESR THESIS v.1/meshes/lidar_link.STL" />
      </geometry>
    </collision>
  </link>
  <joint
    name="lidar_joint"
    type="continuous">
    <origin
      xyz="0.024561 2.068E-05 0.080078"
      rpy="0 0 0" />
    <parent
      link="base_link" />
    <child
      link="lidar_link" />
    <axis
      xyz="0 0 -1" />
  </joint>
  <link
    name="imu_link">
    <inertial>
      <origin
        xyz="-0.00165537333783889 0.000107786090904231 -0.000448013789479707"
        rpy="0 0 0" />
      <mass
        value="0.000529381774423456" />
      <inertia
        ixx="1.33292005146446E-08"
        ixy="5.60536119209215E-12"
        ixz="-6.25784169122668E-14"
        iyy="7.56085417916531E-09"
        iyz="2.9897203630263E-17"
        izz="1.99747898140485E-08" />
    </inertial>
    <visual>
      <origin
        xyz="0 0 0"
        rpy="0 0 0" />
      <geometry>
        <mesh
          filename="package://IRON-X PRO TESR THESIS v.1/meshes/imu_link.STL" />
      </geometry>
      <material
        name="">
        <color
          rgba="0.752941176470588 0.752941176470588 0.752941176470588 1" />
      </material>
    </visual>
    <collision>
      <origin
        xyz="0 0 0"
        rpy="0 0 0" />
      <geometry>
        <mesh
          filename="package://IRON-X PRO TESR THESIS v.1/meshes/imu_link.STL" />
      </geometry>
    </collision>
  </link>
  <joint
    name="imu_joint"
    type="fixed">
    <origin
      xyz="-0.00043943 2.068E-05 0.0020715"
      rpy="0 0 0" />
    <parent
      link="base_link" />
    <child
      link="imu_link" />
    <axis
      xyz="0 0 0" />
  </joint>
</robot>