<?xml version="1.0" encoding="utf-8"?>
<!-- This URDF was automatically created by SolidWorks to URDF Exporter! Originally created by Stephen Brawner (brawner@gmail.com) 
     Commit Version: 1.6.0-4-g7f85cfe  Build Version: 1.6.7995.38578
     For more information, please see http://wiki.ros.org/sw_urdf_exporter -->
<robot
  name="mecanum model v.4">
  <link
    name="base_link">
    <inertial>
      <origin
        xyz="0.00868847650405078 -0.000257115100040666 -0.00100383255756042"
        rpy="0 0 0" />
      <mass
        value="0.438269791762358" />
      <inertia
        ixx="0.000281554923820775"
        ixy="-4.47037724008487E-09"
        ixz="-1.2708786782725E-08"
        iyy="0.000902471808953337"
        iyz="-1.44937525962296E-07"
        izz="0.00114409887764575" />
    </inertial>
    <visual>
      <origin
        xyz="0 0 0"
        rpy="0 0 0" />
      <geometry>
        <mesh
          filename="package://mecanum model v.4/meshes/base_link.STL" />
      </geometry>
      <material
        name="">
        <color
          rgba="0.792156862745098 0.819607843137255 0.933333333333333 1" />
      </material>
    </visual>
    <collision>
      <origin
        xyz="0 0 0"
        rpy="0 0 0" />
      <geometry>
        <mesh
          filename="package://mecanum model v.4/meshes/base_link.STL" />
      </geometry>
    </collision>
  </link>
  <link
    name="Left_front_main_link">
    <inertial>
      <origin
        xyz="1.91651541997517E-08 -1.91454755868459E-09 3.54674939309213E-05"
        rpy="0 0 0" />
      <mass
        value="0.218196881966572" />
      <inertia
        ixx="6.03098003991985E-05"
        ixy="5.46342620592672E-11"
        ixz="2.12557030727322E-11"
        iyy="6.03113932361835E-05"
        iyz="6.32278514410869E-11"
        izz="6.91134863510834E-05" />
    </inertial>
    <visual>
      <origin
        xyz="0 0 0"
        rpy="0 0 0" />
      <geometry>
        <mesh
          filename="package://mecanum model v.4/meshes/Left_front_main_link.STL" />
      </geometry>
      <material
        name="">
        <color
          rgba="0.792156862745098 0.819607843137255 0.933333333333333 1" />
      </material>
    </visual>
    <collision>
      <origin
        xyz="0 0 0"
        rpy="0 0 0" />
      <geometry>
        <mesh
          filename="package://mecanum model v.4/meshes/Left_front_main_link.STL" />
      </geometry>
    </collision>
  </link>
  <joint
    name="Left_front_main"
    type="continuous">
    <origin
      xyz="0.075 0.093 -0.0165"
      rpy="1.5708 0 0" />
    <parent
      link="base_link" />
    <child
      link="Left_front_main_link" />
    <axis
      xyz="0 0 1" />
    <limit
      effort="10"
      velocity="10" />
    <dynamics
      damping="0.1"
      friction="0.1" />
  </joint>
  <link
    name="Right_front_main_link">
    <inertial>
      <origin
        xyz="4.46523888003592E-08 -6.75413587385154E-08 -0.000212318386699786"
        rpy="0 0 0" />
      <mass
        value="0.217950760055372" />
      <inertia
        ixx="6.00995748625438E-05"
        ixy="-7.83278277928891E-11"
        ixz="-2.69815527512961E-11"
        iyy="6.0100935771305E-05"
        iyz="1.81167950824226E-11"
        izz="6.86941143604206E-05" />
    </inertial>
    <visual>
      <origin
        xyz="0 0 0"
        rpy="0 0 0" />
      <geometry>
        <mesh
          filename="package://mecanum model v.4/meshes/Right_front_main_link.STL" />
      </geometry>
      <material
        name="">
        <color
          rgba="0.792156862745098 0.819607843137255 0.933333333333333 1" />
      </material>
    </visual>
    <collision>
      <origin
        xyz="0 0 0"
        rpy="0 0 0" />
      <geometry>
        <mesh
          filename="package://mecanum model v.4/meshes/Right_front_main_link.STL" />
      </geometry>
    </collision>
  </link>
  <joint
    name="Right_front_main"
    type="continuous">
    <origin
      xyz="0.075 -0.093002 -0.0165"
      rpy="1.5708 0 0" />
    <parent
      link="base_link" />
    <child
      link="Right_front_main_link" />
    <axis
      xyz="0 0 -1" />
    <limit
      effort="10"
      velocity="10" />
    <dynamics
      damping="0.1"
      friction="0.1" />
  </joint>
  <link
    name="Right_back_main_link">
    <inertial>
      <origin
        xyz="-3.36449804266836E-08 1.08012634635057E-08 -3.55185643661077E-05"
        rpy="0 0 0" />
      <mass
        value="0.218196600372531" />
      <inertia
        ixx="6.03096002691482E-05"
        ixy="2.39952561726302E-12"
        ixz="3.49640917533502E-13"
        iyy="6.0311444302531E-05"
        iyz="1.18459960092786E-10"
        izz="6.91133917321441E-05" />
    </inertial>
    <visual>
      <origin
        xyz="0 0 0"
        rpy="0 0 0" />
      <geometry>
        <mesh
          filename="package://mecanum model v.4/meshes/Right_back_main_link.STL" />
      </geometry>
      <material
        name="">
        <color
          rgba="0.792156862745098 0.819607843137255 0.933333333333333 1" />
      </material>
    </visual>
    <collision>
      <origin
        xyz="0 0 0"
        rpy="0 0 0" />
      <geometry>
        <mesh
          filename="package://mecanum model v.4/meshes/Right_back_main_link.STL" />
      </geometry>
    </collision>
  </link>
  <joint
    name="Right_back_main"
    type="continuous">
    <origin
      xyz="-0.075 -0.093 -0.0165"
      rpy="1.5708 0 0" />
    <parent
      link="base_link" />
    <child
      link="Right_back_main_link" />
    <axis
      xyz="0 0 -1" />
    <limit
      effort="10"
      velocity="10" />
    <dynamics
      damping="0.1"
      friction="0.1" />
  </joint>
  <link
    name="Left_back_main_link">
    <inertial>
      <origin
        xyz="1.25928190736202E-07 9.02516253536989E-08 0.000212252459011103"
        rpy="0 0 0" />
      <mass
        value="0.217951478604634" />
      <inertia
        ixx="6.00998665627385E-05"
        ixy="-1.35668841049303E-10"
        ixz="2.20302791321124E-11"
        iyy="6.01010944337809E-05"
        iyz="-7.72858410492777E-11"
        izz="6.86943038179532E-05" />
    </inertial>
    <visual>
      <origin
        xyz="0 0 0"
        rpy="0 0 0" />
      <geometry>
        <mesh
          filename="package://mecanum model v.4/meshes/Left_back_main_link.STL" />
      </geometry>
      <material
        name="">
        <color
          rgba="0.792156862745098 0.819607843137255 0.933333333333333 1" />
      </material>
    </visual>
    <collision>
      <origin
        xyz="0 0 0"
        rpy="0 0 0" />
      <geometry>
        <mesh
          filename="package://mecanum model v.4/meshes/Left_back_main_link.STL" />
      </geometry>
    </collision>
  </link>
  <joint
    name="Left_back_main"
    type="continuous">
    <origin
      xyz="-0.075 0.093002 -0.0165"
      rpy="1.5708 0 0" />
    <parent
      link="base_link" />
    <child
      link="Left_back_main_link" />
    <axis
      xyz="0 0 1" />
    <limit
      effort="10"
      velocity="10" />
    <dynamics
      damping="0.1"
      friction="0.1" />
  </joint>
  <link
    name="Realsense_link">
    <inertial>
      <origin
        xyz="-0.0103709928154782 5.64366252200227E-05 -0.000295341784203991"
        rpy="0 0 0" />
      <mass
        value="0.0417075290818711" />
      <inertia
        ixx="3.21186727343634E-05"
        ixy="-6.22845031418555E-09"
        ixz="3.41499561748847E-08"
        iyy="2.82331454727002E-06"
        iyz="1.4476411224919E-08"
        izz="3.16083294429481E-05" />
    </inertial>
    <visual>
      <origin
        xyz="0 0 0"
        rpy="0 0 0" />
      <geometry>
        <mesh
          filename="package://mecanum model v.4/meshes/Realsense_link.STL" />
      </geometry>
      <material
        name="">
        <color
          rgba="0.898039215686275 0.898039215686275 0.898039215686275 1" />
      </material>
    </visual>
    <collision>
      <origin
        xyz="0 0 0"
        rpy="0 0 0" />
      <geometry>
        <mesh
          filename="package://mecanum model v.4/meshes/Realsense_link.STL" />
      </geometry>
    </collision>
  </link>
  <joint
    name="Realsense"
    type="fixed">
    <origin
      xyz="0.125 -0.00024252 0.054467"
      rpy="0 0 0" />
    <parent
      link="base_link" />
    <child
      link="Realsense_link" />
    <axis
      xyz="0 0 0" />
  </joint>
  <link
    name="RPLidar_link">
    <inertial>
      <origin
        xyz="-0.0065667270737461 0.000969221914658544 -0.00888016805798139"
        rpy="0 0 0" />
      <mass
        value="0.142994095653188" />
      <inertia
        ixx="4.62767161181518E-05"
        ixy="-8.53572518984292E-07"
        ixz="-3.62184026396734E-06"
        iyy="7.34746440088868E-05"
        iyz="2.04304178805859E-07"
        izz="0.000107960183716792" />
    </inertial>
    <visual>
      <origin
        xyz="0 0 0"
        rpy="0 0 0" />
      <geometry>
        <mesh
          filename="package://mecanum model v.4/meshes/RPLidar_link.STL" />
      </geometry>
      <material
        name="">
        <color
          rgba="0.101960784313725 0.101960784313725 0.101960784313725 1" />
      </material>
    </visual>
    <collision>
      <origin
        xyz="0 0 0"
        rpy="0 0 0" />
      <geometry>
        <mesh
          filename="package://mecanum model v.4/meshes/RPLidar_link.STL" />
      </geometry>
    </collision>
  </link>
  <joint
    name="RPLidar"
    type="continuous">
    <origin
      xyz="0.0374418238801547 -0.00146432701544818 0.0799184773695659"
      rpy="0 0 0" />
    <parent
      link="base_link" />
    <child
      link="RPLidar_link" />
    <axis
      xyz="0 0 1" />
  </joint>
</robot>